Workbook
Name Company_Name: #REF!
Name Company_Name: [1]Dashboard!$B$2
Name LF: #REF!
Name LF: #REF!
Name LF: #REF!
Name locked: #REF!
Name locked: #REF!
Name locked: #REF!
Name locked: #REF!
Name MPM: #REF!
Name MPM: #REF!
Name MPM: #REF!
Name MPM: #REF!
Name QBCANSUPPORTUPDATE: TRUE
Name QBCOMPANYFILENAME: "\\server1\QBData\QuickbooksData\Gorilla Marketing.qbw"
Name QBENDDATE: 20190831
Name QBHEADERSONSCREEN: FALSE
Name QBMETADATASIZE: 5914
Name QBPRESERVECOLOR: TRUE
Name QBPRESERVEFONT: TRUE
Name QBPRESERVEROWHEIGHT: TRUE
Name QBPRESERVESPACE: TRUE
Name QBREPORTCOLAXIS: 0
Name QBREPORTCOMPANYID: "db4700d490074202ab8a7fff4c5b1188"
Name QBREPORTCOMPARECOL_ANNUALBUDGET: FALSE
Name QBREPORTCOMPARECOL_AVGCOGS: FALSE
Name QBREPORTCOMPARECOL_AVGPRICE: FALSE
Name QBREPORTCOMPARECOL_BUDDIFF: FALSE
Name QBREPORTCOMPARECOL_BUDGET: FALSE
Name QBREPORTCOMPARECOL_BUDPCT: FALSE
Name QBREPORTCOMPARECOL_COGS: FALSE
Name QBREPORTCOMPARECOL_EXCLUDEAMOUNT: FALSE
Name QBREPORTCOMPARECOL_EXCLUDECURPERIOD: FALSE
Name QBREPORTCOMPARECOL_FORECAST: FALSE
Name QBREPORTCOMPARECOL_GROSSMARGIN: FALSE
Name QBREPORTCOMPARECOL_GROSSMARGINPCT: FALSE
Name QBREPORTCOMPARECOL_HOURS: FALSE
Name QBREPORTCOMPARECOL_PCTCOL: FALSE
Name QBREPORTCOMPARECOL_PCTEXPENSE: FALSE
Name QBREPORTCOMPARECOL_PCTINCOME: FALSE
Name QBREPORTCOMPARECOL_PCTOFSALES: FALSE
Name QBREPORTCOMPARECOL_PCTROW: FALSE
Name QBREPORTCOMPARECOL_PPDIFF: FALSE
Name QBREPORTCOMPARECOL_PPPCT: FALSE
Name QBREPORTCOMPARECOL_PREVPERIOD: FALSE
Name QBREPORTCOMPARECOL_PREVYEAR: FALSE
Name QBREPORTCOMPARECOL_PYDIFF: FALSE
Name QBREPORTCOMPARECOL_PYPCT: FALSE
Name QBREPORTCOMPARECOL_QTY: FALSE
Name QBREPORTCOMPARECOL_RATE: FALSE
Name QBREPORTCOMPARECOL_TRIPBILLEDMILES: FALSE
Name QBREPORTCOMPARECOL_TRIPBILLINGAMOUNT: FALSE
Name QBREPORTCOMPARECOL_TRIPMILES: FALSE
Name QBREPORTCOMPARECOL_TRIPNOTBILLABLEMILES: FALSE
Name QBREPORTCOMPARECOL_TRIPTAXDEDUCTIBLEAMOUNT: FALSE
Name QBREPORTCOMPARECOL_TRIPUNBILLEDMILES: FALSE
Name QBREPORTCOMPARECOL_YTD: FALSE
Name QBREPORTCOMPARECOL_YTDBUDGET: FALSE
Name QBREPORTCOMPARECOL_YTDPCT: FALSE
Name QBREPORTROWAXIS: 9

Sheet Docket
A1: MONTHLY ACCOUNTING FILE DOCKET SHEET
A4: NAME OF ENTITY: | C4: Aura
A6: MONTH: | C6: 45474
A10: FINANCIAL REPORT PROCESSING
D12: BY | F12: DATE
A13: ACCOUNTING WORK PAPERS PREPARED | D13: XY
A15: REVIEW OF ACCOUNTING WORK PAPERS - SUPERVISOR
A17: REVIEW OF ACCOUNTING WORK PAPERS - MANAGER
A19: FINAL REVIEW & APPROVAL
A21: SPECIAL INSTRUCTIONS, QUARTER END
D22: BY | F22: DATE
A23: TYPE FINANCIAL REPORTS FOR INVESTORS
A25: OBTAIN FIXED ASSETS FORECAST
A27: DETERMINE DISTRIBUTION AMOUNT
A29: CREATE NEWSLETTER FINANCIALS, SAVE TO SHARED FOLDER
A31: COMMENTS:

Sheet Notes
E1: Date: | F1: =NOW() -> 46065.348
E2: Prepared By: | F2: =Docket!D13 -> XY | G2: =NOW() -> 46065.348
E3: Approved By:
F4: Initial | G4: Date
A5: =+Docket!C4 -> Aura
A6: Accountant Notes for Month End
A8: Month: | C8: =+Docket!C6 -> 45474
A11: Overall notes for entire book:
B14: GL Acct # | C14: GL Name | D14: Notes
B16: 1126 | C16: A/R - Vendors
B18: 1128 | C18: A/R - Payroll
B20: 1155
B22: 1163
B24: 1875 | C24: Security Deposit
B26: 2036 | C26: Employee Trust
B28: 2038 | C28: Other Payroll Liabilities
A36: Note:

Sheet Access List
A1: CLIENT NAME:
A3: BANK / CC NAME | B3: OTHER PLATFORM | C3: ACCOUNT NUMBER | D3: ITEM NEEDED | E3: ACCESS (Y/N) | F3: NOTES
A4: Bank of America | C4: 3251-5870-1020 | D4: Bank Statements | E4: Y
A5: ADP - AuraAccounting
A6: ADP - SeedCMS (Socal)

Sheet Contact List
A1: CLIENT NAME:
A3: CONTACT | B3: ITEMS NEEDED (add acct # if needed)
A4: Carlos Roman <carlos@carefreeboats.com> | B4: main contact for month-end questions
A5: Peter Yanakiev <peter@carefreeboats.com> | B5: for bank and cc statements

Sheet TB Match
B1: 46022
B2: Debit | C2: Credit | E2: Debit | F2: Credit
A3: 10000 Business Adv Relationship - 1020 | B3: ='10000 - BofA CHK 1020'!$O$45 -> 25944.2 | E3: 25944.2 | G3: =(B3+C3)-(E3+F3) -> 0 | H3: =IF(ROUND(B3-E3,1)= 0, "Match","No Match") -> Match | I3: =IF(ROUND(C3-F3,1)= 0, "Match","No Match") -> Match
A4: 11000 Accounts Receivable | B4: ='11000 Accounts Receivable'!C11 -> 0 | E4: 0 | G4: =(B4+C4)-(E4+F4) -> 0 | H4: =IF(ROUND(B4-E4,1)= 0, "Match","No Match") -> Match | I4: =IF(ROUND(C4-F4,1)= 0, "Match","No Match") -> Match
A5: 11600 Prepaid expenses | B5: ='11600 - Prepaid Expenses (OLD)'!E19 -> 39826.575 | E5: 39826.57 | G5: =(B5+C5)-(E5+F5) -> 0.0049544403 | H5: =IF(ROUND(B5-E5,1)= 0, "Match","No Match") -> Match | I5: =IF(ROUND(C5-F5,1)= 0, "Match","No Match") -> Match
A6: 13000 Axopar Suntop 37 | B6: ='15500-Acc Depreciation'!AM8 -> 269900 | E6: 269900 | G6: =(B6+C6)-(E6+F6) -> 0 | H6: =IF(ROUND(B6-E6,1)= 0, "Match","No Match") -> Match | I6: =IF(ROUND(C6-F6,1)= 0, "Match","No Match") -> Match
A7: 13100 Beneteau Flyer 9 | B7: ='15500-Acc Depreciation'!AM7 -> 263992.78 | E7: 263992.78 | G7: =(B7+C7)-(E7+F7) -> 0 | H7: =IF(ROUND(B7-E7,1)= 0, "Match","No Match") -> Match | I7: =IF(ROUND(C7-F7,1)= 0, "Match","No Match") -> Match
A8: 13200 Manitou 25 Oasis | B8: ='15500-Acc Depreciation'!AM4 -> 66464 | E8: 66464 | G8: =(B8+C8)-(E8+F8) -> 0 | H8: =IF(ROUND(B8-E8,1)= 0, "Match","No Match") -> Match | I8: =IF(ROUND(C8-F8,1)= 0, "Match","No Match") -> Match
A9: 13400 NX 340 Sport Coupe | B9: ='15500-Acc Depreciation'!AM10 -> 272754.5 | E9: 272754.5 | G9: =(B9+C9)-(E9+F9) -> 0 | H9: =IF(ROUND(B9-E9,1)= 0, "Match","No Match") -> Match | I9: =IF(ROUND(C9-F9,1)= 0, "Match","No Match") -> Match
A10: 13500 Axopar T-Top 28 | B10: ='15500-Acc Depreciation'!AM9 -> 140000 | E10: 140000 | G10: =(B10+C10)-(E10+F10) -> 0 | H10: =IF(ROUND(B10-E10,1)= 0, "Match","No Match") -> Match | I10: =IF(ROUND(C10-F10,1)= 0, "Match","No Match") -> Match
A11: 15000 Pacific Boat Club Fleet | B11: ='15500-Acc Depreciation'!AP6 -> 68219.69 | E11: 68219.69 | G11: =(B11+C11)-(E11+F11) -> 0 | H11: =IF(ROUND(B11-E11,1)= 0, "Match","No Match") -> Match | I11: =IF(ROUND(C11-F11,1)= 0, "Match","No Match") -> Match
A12: 15500 Accumulated Depreciation | C12: =_xlfn.XLOOKUP(B1,'15500-Acc Depreciation'!33:33,'15500-Acc Depreciation'!43:43) -> 530560.76 | F12: 530560.76 | G12: =(B12+C12)-(E12+F12) -> 0.0016666667 | H12: =IF(ROUND(B12-E12,1)= 0, "Match","No Match") -> Match | I12: =IF(ROUND(C12-F12,1)= 0, "Match","No Match") -> Match
A13: 17000 Goodwill | B13: ='17000 - Goodwill'!B3 -> 174500 | E13: 174500 | G13: =(B13+C13)-(E13+F13) -> 0 | H13: =IF(ROUND(B13-E13,1)= 0, "Match","No Match") -> Match | I13: =IF(ROUND(C13-F13,1)= 0, "Match","No Match") -> Match
A14: 18000 Accumulated Amortization | C14: =_xlfn.XLOOKUP(B1,'17000 - Goodwill'!A:A,'17000 - Goodwill'!D:D) -> 51357 | F14: 51357 | G14: =(B14+C14)-(E14+F14) -> 0 | H14: =IF(ROUND(B14-E14,1)= 0, "Match","No Match") -> Match | I14: =IF(ROUND(C14-F14,1)= 0, "Match","No Match") -> Match
A15: 21000 Accrued Expenses | C15: ='21000 - Accrued Expenses'!H23 -> 3149.75 | F15: 3149.75 | G15: =(B15+C15)-(E15+F15) -> 0 | H15: =IF(ROUND(B15-E15,1)= 0, "Match","No Match") -> Match | I15: =IF(ROUND(C15-F15,1)= 0, "Match","No Match") -> Match
A16: 21050 Accrued Interest | C16: ='21050 - Accrued Interest'!E8 -> 794.18231 | F16: 794.17 | G16: =(B16+C16)-(E16+F16) -> 0.012310814 | H16: =IF(ROUND(B16-E16,1)= 0, "Match","No Match") -> Match | I16: =IF(ROUND(C16-F16,1)= 0, "Match","No Match") -> Match
A17: 21100 Accrued Payroll | C17: 0 | F17: 0 | G17: =(B17+C17)-(E17+F17) -> 0 | H17: =IF(ROUND(B17-E17,1)= 0, "Match","No Match") -> Match | I17: =IF(ROUND(C17-F17,1)= 0, "Match","No Match") -> Match
A18: 21101 Accrued Payroll:Officer Wages Payable | C18: ='21100 - Accrued Payroll'!J21 -> 2245.52 | F18: 2245.52 | G18: =(B18+C18)-(E18+F18) -> 4.0927262e-12 | H18: =IF(ROUND(B18-E18,1)= 0, "Match","No Match") -> Match | I18: =IF(ROUND(C18-F18,1)= 0, "Match","No Match") -> Match
A19: 21102 Accrued Payroll:Contractor Wages Payable | C19: ='21100 - Accrued Payroll'!B31 -> 7930.81 | F19: 7930.81 | G19: =(B19+C19)-(E19+F19) -> 0 | H19: =IF(ROUND(B19-E19,1)= 0, "Match","No Match") -> Match | I19: =IF(ROUND(C19-F19,1)= 0, "Match","No Match") -> Match
A20: 21125 Unearned Revenue | C20: =_xlfn.XLOOKUP(B1,'21125 - Unearned Revenue'!3:3,'21125 - Unearned Revenue'!133:133) -> 442379.08 | F20: 442379.08 | G20: =(B20+C20)-(E20+F20) -> 0.0033333332 | H20: =IF(ROUND(B20-E20,1)= 0, "Match","No Match") -> Match | I20: =IF(ROUND(C20-F20,1)= 0, "Match","No Match") -> Match
A21: 21150 Loan From Shareholder - CCM Integrated | C21: =F21 -> 26221.5 | F21: 26221.5 | G21: =(B21+C21)-(E21+F21) -> 0 | H21: =IF(ROUND(B21-E21,1)= 0, "Match","No Match") -> Match | I21: =IF(ROUND(C21-F21,1)= 0, "Match","No Match") -> Match
A22: 21200 Loan From Shareholder - Carlos Roman | C22: =F22 -> 55668.06 | F22: 55668.06 | G22: =(B22+C22)-(E22+F22) -> 0 | H22: =IF(ROUND(B22-E22,1)= 0, "Match","No Match") -> Match | I22: =IF(ROUND(C22-F22,1)= 0, "Match","No Match") -> Match
A23: 21300 Due To/From SoCal Nautical | C23: =_xlfn.XLOOKUP("TOTAL",'21300 - Due to.from Socal'!I22,'21300 - Due to.from Socal'!J22) -> 53375.07 | F23: 53375.07 | G23: =(B23+C23)-(E23+F23) -> 0 | H23: =IF(ROUND(B23-E23,1)= 0, "Match","No Match") -> Match | I23: =IF(ROUND(C23-F23,1)= 0, "Match","No Match") -> Match
A24: 21350 Insurance Payable | C24: =_xlfn.XLOOKUP(B1,'23500 - Insurance Payable'!A:A,'23500 - Insurance Payable'!N:N,) -> 31127.185 | F24: 31127.18 | G24: =(B24+C24)-(E24+F24) -> 0.0050043987 | H24: =IF(ROUND(B24-E24,1)= 0, "Match","No Match") -> Match | I24: =IF(ROUND(C24-F24,1)= 0, "Match","No Match") -> Match
A25: 22000 Short-term business loans:ST - Axopar Suntop 37 Loan | C25: ='22000 & 23000 - Axopar Suntop37'!N5 -> 0.00045266328 | F25: 0 | G25: =(B25+C25)-(E25+F25) -> 0.00045266328 | H25: =IF(ROUND(B25-E25,1)= 0, "Match","No Match") -> Match | I25: =IF(ROUND(C25-F25,1)= 0, "Match","No Match") -> Match
A26: 22050 Short-term business loans:ST - Beneteau Flyer 9 | C26: ='22050 & 23050 - Beneteau'!N5 -> 0.00012240116 | F26: 0 | G26: =(B26+C26)-(E26+F26) -> 0.00012240116 | H26: =IF(ROUND(B26-E26,1)= 0, "Match","No Match") -> Match | I26: =IF(ROUND(C26-F26,1)= 0, "Match","No Match") -> Match
A27: 22100 Short-term business loans:ST - Manitou 25 Oasis Loan | C27: ='22100 & 23100 -Manitou (Stacey)'!N5 -> 0.00041830339 | F27: 0 | G27: =(B27+C27)-(E27+F27) -> 0.00041830339 | H27: =IF(ROUND(B27-E27,1)= 0, "Match","No Match") -> Match | I27: =IF(ROUND(C27-F27,1)= 0, "Match","No Match") -> Match
A28: 22150 Short-term business loans:ST - Scott Tiernan Note | C28: ='22150 & 23150 - Scott Tiernan'!N7 -> 5990.5163 | F28: 5990.53 | G28: =(B28+C28)-(E28+F28) -> -0.013738853 | H28: =IF(ROUND(B28-E28,1)= 0, "Match","No Match") -> Match | I28: =IF(ROUND(C28-F28,1)= 0, "Match","No Match") -> Match
A29: 22250 Short-term business loans:ST - NX 340 Sport Coupe Loan | C29: ='22250 & 23250 - NX 340'!N5 -> -0.00020420778 | F29: 0 | G29: =(B29+C29)-(E29+F29) -> -0.00020420778 | H29: =IF(ROUND(B29-E29,1)= 0, "Match","No Match") -> Match | I29: =IF(ROUND(C29-F29,1)= 0, "Match","No Match") -> Match
A30: 22300 Short-term business loans:ST - Axopar T-Top 28 Loan | C30: ='22300 & 23300 - Axopar T-TOP28'!O5 -> 4.9079157e-05 | F30: 0 | G30: =(B30+C30)-(E30+F30) -> 4.9079157e-05 | H30: =IF(ROUND(B30-E30,1)= 0, "Match","No Match") -> Match | I30: =IF(ROUND(C30-F30,1)= 0, "Match","No Match") -> Match
A31: 23000 Long-term business loans:LT - Axopar Suntop 37 Loan | C31: ='22000 & 23000 - Axopar Suntop37'!N6 -> -0.0043644141 | F31: 0 | G31: =(B31+C31)-(E31+F31) -> -0.0043644141 | H31: =IF(ROUND(B31-E31,1)= 0, "Match","No Match") -> Match | I31: =IF(ROUND(C31-F31,1)= 0, "Match","No Match") -> Match
A32: Short-term business loans:22350 ST - CCJ True, LLC Loan | C32: ='23350 - CCJ True Loan'!N5 -> 130327.01 | F32: 130327.01 | G32: =(B32+C32)-(E32+F32) -> 0.0028861333 | H32: =IF(ROUND(B32-E32,1)= 0, "Match","No Match") -> Match | I32: =IF(ROUND(C32-F32,1)= 0, "Match","No Match") -> Match
A33: Short-term business loans:22400 ST - CCJ True, LLC Loan (2) | C33: ='23400 - CCJ True Loan (2)'!N5 -> 18327.425 | F33: 18327.44 | G33: =(B33+C33)-(E33+F33) -> -0.015373183 | H33: =IF(ROUND(B33-E33,1)= 0, "Match","No Match") -> Match | I33: =IF(ROUND(C33-F33,1)= 0, "Match","No Match") -> Match
A34: 23050 Long-term business loans:LT - Beneteau Flyer 9 | C34: ='22050 & 23050 - Beneteau'!N6 -> -0.0011801475 | F34: 0 | G34: =(B34+C34)-(E34+F34) -> -0.0011801475 | H34: =IF(ROUND(B34-E34,1)= 0, "Match","No Match") -> Match | I34: =IF(ROUND(C34-F34,1)= 0, "Match","No Match") -> Match
A35: 23100 Long-term business loans:LT - Manitou 25 Oasis Loan | C35: ='22100 & 23100 -Manitou (Stacey)'!N6 -> -0.0052525712 | F35: =0 -> 0 | G35: =(B35+C35)-(E35+F35) -> -0.0052525712 | H35: =IF(ROUND(B35-E35,1)= 0, "Match","No Match") -> Match | I35: =IF(ROUND(C35-F35,1)= 0, "Match","No Match") -> Match
A36: 23150 Long-term business loans:LT - Scott Tiernan Note | C36: 0 | F36: =0 -> 0 | G36: =(B36+C36)-(E36+F36) -> 0 | H36: =IF(ROUND(B36-E36,1)= 0, "Match","No Match") -> Match | I36: =IF(ROUND(C36-F36,1)= 0, "Match","No Match") -> Match
A37: 23250 Long-term business loans:LT - NX 340 Sport Coupe Loan | C37: ='22250 & 23250 - NX 340'!N6 -> 0.0023811026 | F37: 0 | G37: =(B37+C37)-(E37+F37) -> 0.0023811026 | H37: =IF(ROUND(B37-E37,1)= 0, "Match","No Match") -> Match | I37: =IF(ROUND(C37-F37,1)= 0, "Match","No Match") -> Match
A38: 23300 Long-term business loans:LT - Axopar T-Top 28 Loan | C38: ='22300 & 23300 - Axopar T-TOP28'!O6 -> -0.00043606231 | F38: 0 | G38: =(B38+C38)-(E38+F38) -> -0.00043606231 | H38: =IF(ROUND(B38-E38,1)= 0, "Match","No Match") -> Match | I38: =IF(ROUND(C38-F38,1)= 0, "Match","No Match") -> Match
A39: Long-term business loans:23350 LT - CCJ True, LLC Loan | C39: ='23350 - CCJ True Loan'!N6 -> 332358.97 | F39: 332358.97 | G39: =(B39+C39)-(E39+F39) -> -0.00054299622 | H39: =IF(ROUND(B39-E39,1)= 0, "Match","No Match") -> Match | I39: =IF(ROUND(C39-F39,1)= 0, "Match","No Match") -> Match
A40: Long-term business loans:23400 LT - CCJ True, LLC Loan (2) | C40: ='23400 - CCJ True Loan (2)'!N6 -> 49058.992 | F40: 49058.99 | G40: =(B40+C40)-(E40+F40) -> 0.0018441177 | H40: =IF(ROUND(B40-E40,1)= 0, "Match","No Match") -> Match | I40: =IF(ROUND(C40-F40,1)= 0, "Match","No Match") -> Match
...

Sheet 10000 - BofA CHK 1020
A1: 10000 - Bank of America Checking 1020 | O1: **add screenshot of bank stmt
A3: Beginning Balance | O3: 62443.29
A5: Checks & Payments | O5: -93222.5
A8: Deposits & Credits | O8: 56723.41
A10: Service Charges | O10: 0
A12: Statement Balance | O12: =O3+O5+O8+O10 -> 25944.2
A14: Uncleared Transactions | O14: =G41 -> 0
A16: Cleared Balance Uncleared Transactions Checks and Payments - 0 items
A41: Total Checks and Payments | G41: =SUM(F17:F39) -> 0
A42: Total Uncleared Transactions | G42: =G41 -> 0
A43: Expand for detail
A45: Book Balance | O45: =O12+O14 -> 25944.2

Sheet 11000 Accounts Receivable
A1: PLEASE REFER TO PAYSIMPLE QB WORKPAPER
B5: Bank Deposits | C5: 0 | D5: Hits in next month
B6: initiation fees not paid | C6: 0
B7: Not Cleared | C7: 0
B8: WRITE OFF AMOUNT | C8: 0
B11: A/R ENDING BALANCE | C11: 0
B12: G/L | C12: 0
B13: Difference | C13: 0

Sheet 11600 - Prepaid Expenses
A1: GL Date | B1: Name | C1: Amount | D1: Period | E1: Total Amortized | F1: 45261 | G1: 45292 | H1: 45323 | I1: 45352 | J1: 45383 | K1: 45413 | L1: 45444 | M1: 45474 | N1: 45505 | O1: 45536 | P1: 45566 | Q1: 45597 | R1: 45627 | S1: 45658 | T1: 45689 | U1: 45717 | V1: 45748 | W1: 45778 | X1: 45809 | Y1: 45839 | Z1: 45870 | AA1: 45901 | AB1: 45931 | AC1: 45962 | AD1: 45992 | AE1: 46023 | AF1: 46054 | AG1: 46082 | AH1: 46113 | AI1: 46143 | AJ1: 46174 | AK1: 46204 | AL1: 46235 | AM1: 46266 | AN1: 46296 | AO1: 46327 | AP1: 46357 | AQ1: remaining
A2: 45627 | B2: First Insurance | C2: 39809.21 | D2: 1/1/25-12/31-2025 | E2: =SUM(G2:AD2) -> 39809.21 | S2: =C2/12 -> 3317.4342 | T2: =S2 -> 3317.4342 | U2: =T2 -> 3317.4342 | V2: =U2 -> 3317.4342 | W2: =V2 -> 3317.4342 | X2: =W2 -> 3317.4342 | Y2: =X2 -> 3317.4342 | Z2: =Y2 -> 3317.4342 | AA2: =Z2 -> 3317.4342 | ... AD2: =AC2 -> 3317.4342 | AQ2: =C2-SUM(F2:AD2) -> 0
A3: 45864 | B3: GoDaddy Renewal | C3: 1159.06 | D3: 45870 | E3: =SUM(G3:AD3) -> 241.47083 | Z3: =C3/24 -> 48.294167 | AA3: =Z3 -> 48.294167 | AB3: =AA3 -> 48.294167 | AC3: =AB3 -> 48.294167 | AD3: =AC3 -> 48.294167 | AE3: =AD3 -> 48.294167 | AF3: =AE3 -> 48.294167 | AG3: =AF3 -> 48.294167 | AH3: =AG3 -> 48.294167 | ... AP3: =AO3 -> 48.294167 | AQ3: =C3-SUM(F3:AD3) -> 917.58917
A4: 45873 | B4: STATE COMP INSURANCE | C4: 1402.46 | D4: 45901 | E4: =SUM(G4:AD4) -> 1402.46 | AA4: 288.43 | AB4: 288.43 | AC4: =825.6-226 -> 599.6 | AD4: 226 | AQ4: =C4-SUM(F4:AD4) -> 0
A5: 45961 | B5: First Insurance (Adjustment) | C5: =-'21350 - Insurance Payable'!M44 -> -1942.5955 | D5: 10/1/25-12/31/25 | E5: =SUM(G5:AD5) -> -1942.6 | AB5: =-1942.6/3 -> -647.53333 | AC5: =AB5 -> -647.53333 | AD5: =AC5 -> -647.53333 | AQ5: =C5-SUM(F5:AD5) -> 0.0045322752
A6: 45991 | B6: First Insurance | C6: 38908.981 | D6: 1/1/26-12/31-2026 | E6: =SUM(G6:AD6) -> 0 | AE6: =38908.98/12 -> 3242.415 | AF6: =AE6 -> 3242.415 | AG6: =AF6 -> 3242.415 | AH6: =AG6 -> 3242.415 | AI6: =AH6 -> 3242.415 | AJ6: =AI6 -> 3242.415 | AK6: =AJ6 -> 3242.415 | AL6: =AK6 -> 3242.415 | AM6: =AL6 -> 3242.415 | ... AP6: =AO6 -> 3242.415 | AQ6: =C6-SUM(F6:AD6) -> 38908.981
C7: =SUM(C2:C6) -> 79337.116 | E7: =SUM(E2:E6) -> 39510.541 | F7: 0 | G7: =SUM(G2:G6) -> 0 | H7: =SUM(H2:H6) -> 0 | I7: =SUM(I2:I6) -> 0 | J7: =SUM(J2:J6) -> 0 | K7: =SUM(K2:K6) -> 0 | L7: =SUM(L2:L6) -> 0 | M7: =SUM(M2:M6) -> 0 | N7: =SUM(N2:N6) -> 0 | ... AQ7: =SUM(AQ2:AQ6) -> 39826.575
X9: The balance is now a payable - paid this on 12/30/25.
D12: Total Prepaid | E12: =C7-E7 -> 39826.575
D13: Sitting in G/L | E13: 39826.57
D14: Difference | E14: =E12-E13 -> 0.0049544402
X30: Expense prior payroll journal matches premium premium charge of $356.01

Sheet 11600 - Prepaid Expenses (OLD)
A1: GL Date | B1: Name | C1: Amount | D1: Period | E1: Total Amortized | F1: 45261 | G1: 45292 | H1: 45323 | I1: 45352 | J1: 45383 | K1: 45413 | L1: 45444 | M1: 45474 | N1: 45505 | O1: 45536 | P1: 45566 | Q1: 45597 | R1: 45627 | S1: 45658 | T1: 45689 | U1: 45717 | V1: 45748 | W1: 45778 | X1: 45809 | Y1: 45839 | Z1: 45870 | AA1: 45901 | AB1: 45931 | AC1: 45962 | AD1: 45992 | AE1: 46023 | AF1: 44958 | AG1: remaining
A2: 45277 | B2: First Insurance | C2: 51710 | D2: 1/1/24-12/31/24 | E2: =SUM(G2:AD2) -> 51710 | G2: 4309.17 | H2: =G2 -> 4309.17 | I2: =H2 -> 4309.17 | J2: =I2 -> 4309.17 | K2: =J2 -> 4309.17 | L2: =K2 -> 4309.17 | M2: =L2 -> 4309.17 | N2: =M2 -> 4309.17 | O2: =N2 -> 4309.17 | ... Q2: =P2 -> 4309.17 | R2: =Q2-0.04 -> 4309.13 | AG2: =C2-SUM(F2:AF2) -> 0
A3: 45488 | B3: First Insurance | C3: -993.2 | D3: 7/1-12/31 | E3: =SUM(G3:AD3) -> -993.2 | M3: -165.53333 | N3: -165.53333 | O3: -165.53333 | P3: -165.53333 | Q3: -165.53333 | R3: -165.53333 | AG3: =C3-SUM(F3:AF3) -> 0
A4: 45627 | B4: First Insurance | C4: 39809.21 | D4: 1/1/25-12/31-2025 | E4: =SUM(G4:AD4) -> 39809.21 | S4: =C4/12 -> 3317.4342 | T4: =S4 -> 3317.4342 | U4: =T4 -> 3317.4342 | V4: =U4 -> 3317.4342 | W4: =V4 -> 3317.4342 | X4: =W4 -> 3317.4342 | Y4: =X4 -> 3317.4342 | Z4: =Y4 -> 3317.4342 | AA4: =Z4 -> 3317.4342 | ... AD4: =AC4 -> 3317.4342 | AG4: =C4-SUM(F4:AF4) -> 0
A5: 45656 | B5: STATE COMP INSURANCE | C5: 501.75 | D5: 45658 | E5: =SUM(G5:AD5) -> 501.75 | S5: =C5 -> 501.75 | AG5: =C5-SUM(F5:AF5) -> 0
A6: 45747 | B6: AURA ACCOUNTING | C6: 2287.69 | D6: 45748 | E6: =SUM(G6:AD6) -> 2287.69 | V6: =C6 -> 2287.69 | AG6: =C6-SUM(F6:AF6) -> 0
A7: 45775 | B7: Newport International Boat Show | C7: 5870.57 | D7: 45778 | E7: =SUM(G7:AD7) -> 5870.57 | W7: =C7 -> 5870.57 | AG7: =C7-SUM(F7:AF7) -> 0
A8: 45864 | B8: GoDaddy Renewal | C8: 1159.06 | D8: 45870 | E8: =SUM(G8:AD8) -> 241.47083 | Z8: =C8/24 -> 48.294167 | AA8: =Z8 -> 48.294167 | AB8: =AA8 -> 48.294167 | AC8: =AB8 -> 48.294167 | AD8: =AC8 -> 48.294167 | AE8: =AD8 -> 48.294167 | AF8: =AE8 -> 48.294167 | AG8: =C8-SUM(F8:AF8) -> 821.00083
A9: 45873 | B9: STATE COMP INSURANCE | C9: 1402.46 | D9: 45901 | E9: =SUM(G9:AD9) -> 1402.46 | AA9: 288.43 | AB9: 288.43 | AC9: =825.6-226 -> 599.6 | AD9: 226 | AG9: =C9-SUM(F9:AF9) -> 0
A10: 45961 | B10: AURA ACCOUNTING | C10: 2402.07 | D10: 45962 | E10: =SUM(G10:AD10) -> 2402.07 | AC10: 2402.07 | AG10: =C10-SUM(F10:AF10) -> 0
A11: 45961 | B11: First Insurance (Adjustment) | C11: =-'21350 - Insurance Payable'!M44 -> -1942.5955 | D11: 10/1/25-12/31/25 | E11: =SUM(G11:AD11) -> -1942.6 | AB11: =-1942.6/3 -> -647.53333 | AC11: =AB11 -> -647.53333 | AD11: =AC11 -> -647.53333 | AG11: =C11-SUM(F11:AF11) -> 0.0045322752
A12: 45991 | B12: First Insurance | C12: 38908.981 | D12: 1/1/26-12/31-2026 | E12: =SUM(G12:AD12) -> 0 | AE12: =38908.98/12 -> 3242.415 | AF12: =AE12 -> 3242.415 | AG12: =C12-SUM(F12:AF12) -> 32424.151
E13: =SUM(G13:AD13) -> 0 | AG13: =C13-SUM(F13:AF13) -> 0
C14: =SUM(C2:C13) -> 141116 | E14: =SUM(E2:E13) -> 101289.42 | F14: 0 | G14: =SUM(G2:G13) -> 4309.17 | H14: =SUM(H2:H13) -> 4309.17 | I14: =SUM(I2:I13) -> 4309.17 | J14: =SUM(J2:J13) -> 4309.17 | K14: =SUM(K2:K13) -> 4309.17 | L14: =SUM(L2:L13) -> 4309.17 | M14: =SUM(M2:M13) -> 4143.6367 | N14: =SUM(N2:N13) -> 4143.6367 | ... AF14: =SUM(AF2:AF13) -> 3290.7092
X16: The balance is now a payable - paid this on 12/30/25.
D19: Total Prepaid | E19: =C14-E14 -> 39826.575
D20: Sitting in G/L | E20: 39826.57
D21: Difference | E21: =E19-E20 -> 0.0049544403
X37: Expense prior payroll journal matches premium premium charge of $356.01

Sheet 15500-Acc Depreciation
A2: Assets
B3: Life | C3: 44439 | D3: =EOMONTH(C3,1) -> 44469 | E3: =EOMONTH(D3,1) -> 44500 | F3: =EOMONTH(E3,1) -> 44530 | G3: =EOMONTH(F3,1) -> 44561 | H3: =EOMONTH(G3,1) -> 44592 | I3: =EOMONTH(H3,1) -> 44620 | J3: =EOMONTH(I3,1) -> 44651 | K3: =EOMONTH(J3,1) -> 44681 | ... EQ3: =EOMONTH(EP3,1) -> 48822
A4: MANITOU 25 OASIS | B4: 7 | C4: 66464 | D4: =C4 -> 66464 | E4: =D4 -> 66464 | F4: =E4 -> 66464 | G4: =F4 -> 66464 | H4: =G4 -> 66464 | I4: =H4 -> 66464 | J4: =I4 -> 66464 | K4: =J4 -> 66464 | ... EQ4: =EP4 -> 66464
A5: SEA RAY 34 SUNDANCER | B5: 7 | C5: 65000 | D5: =C5 -> 65000 | E5: =D5 -> 65000 | F5: =E5 -> 65000 | G5: =F5 -> 65000 | H5: =G5 -> 65000 | I5: =H5 -> 65000 | J5: =I5 -> 65000 | K5: =J5 -> 65000 | ... AJ5: =AI5 -> 65000
A6: PACIFIC BOAT CLUB FLEET | B6: 7 | H6: 150000 | I6: =H6 -> 150000 | J6: =I6 -> 150000 | K6: =J6 -> 150000 | L6: =K6 -> 150000 | M6: =L6 -> 150000 | N6: =M6 -> 150000 | O6: =N6 -> 150000 | P6: =O6 -> 150000 | ... T6: =S6 -> 150000 | U6: =T6-32069 -> 117931 | V6: =U6 -> 117931 | W6: =V6 -> 117931 | X6: =W6-27648 -> 90283 | Y6: =X6 -> 90283 | Z6: =Y6 -> 90283 | AA6: =Z6 -> 90283 | AB6: =AA6 -> 90283 | AC6: =AB6 -> 90283 | AD6: =AC6 -> 90283 | AE6: =AD6 -> 90283 | AF6: =AE6 -> 90283 | ... AO6: =AN6 -> 90283 | AP6: =AO6-22063.31 -> 68219.69 | AQ6: =AP6 -> 68219.69 | AR6: =AQ6 -> 68219.69 | AS6: =AR6 -> 68219.69 | AT6: =AS6 -> 68219.69 | AU6: =AT6 -> 68219.69 | AV6: =AU6 -> 68219.69 | AW6: =AV6 -> 68219.69 | AX6: =AW6 -> 68219.69 | ... EQ6: =EP6 -> 68219.69
A7: BENETEAU FLYER 9 | B7: 7 | I7: 263992.78 | J7: =I7 -> 263992.78 | K7: =J7 -> 263992.78 | L7: =K7 -> 263992.78 | M7: =L7 -> 263992.78 | N7: =M7 -> 263992.78 | O7: =N7 -> 263992.78 | P7: =O7 -> 263992.78 | Q7: =P7 -> 263992.78 | ... EQ7: =EP7 -> 263992.78
A8: AXOPAR SUNTOP 37 | B8: 7 | J8: 269900 | K8: =J8 -> 269900 | L8: =K8 -> 269900 | M8: =L8 -> 269900 | N8: =M8 -> 269900 | O8: =N8 -> 269900 | P8: =O8 -> 269900 | Q8: =P8 -> 269900 | R8: =Q8 -> 269900 | ... EQ8: =EP8 -> 269900
A9: Axopar T-Top 28 | B9: 7 | Z9: 140000 | AA9: =Z9 -> 140000 | AB9: =AA9 -> 140000 | AC9: =AB9 -> 140000 | AD9: =AC9 -> 140000 | AE9: =AD9 -> 140000 | AF9: =AE9 -> 140000 | AG9: =AF9 -> 140000 | AH9: =AG9 -> 140000 | ... EQ9: =EP9 -> 140000
A10: NX 340 Sport Cruisr | B10: 7 | Z10: 272754.5 | AA10: =Z10 -> 272754.5 | AB10: =AA10 -> 272754.5 | AC10: =AB10 -> 272754.5 | AD10: =AC10 -> 272754.5 | AE10: =AD10 -> 272754.5 | AF10: =AE10 -> 272754.5 | AG10: =AF10 -> 272754.5 | AH10: =AG10 -> 272754.5 | ... EQ10: =EP10 -> 272754.5
A12: Total | C12: =SUM(C4:C11) -> 131464 | D12: =SUM(D4:D11) -> 131464 | E12: =SUM(E4:E11) -> 131464 | F12: =SUM(F4:F11) -> 131464 | G12: =SUM(G4:G11) -> 131464 | H12: =SUM(H4:H11) -> 281464 | I12: =SUM(I4:I11) -> 545456.78 | J12: =SUM(J4:J11) -> 815356.78 | ... EQ12: =SUM(EQ4:EQ11) -> 1081331
A15: Monthly Depreciation
C17: =C3 -> 44439 | D17: =EOMONTH(C17,1) -> 44469 | E17: =EOMONTH(D17,1) -> 44500 | F17: =EOMONTH(E17,1) -> 44530 | G17: =EOMONTH(F17,1) -> 44561 | H17: =EOMONTH(G17,1) -> 44592 | I17: =EOMONTH(H17,1) -> 44620 | J17: =EOMONTH(I17,1) -> 44651 | K17: =EOMONTH(J17,1) -> 44681 | ... EQ17: =EOMONTH(EP17,1) -> 48822
A18: MANITOU 25 OASIS | C18: =IFERROR(C4/(12*$B4),0)+5538.67 -> 6329.9081 | D18: =IFERROR(D4/(12*$B4),0) -> 791.2381 | E18: =IFERROR(E4/(12*$B4),0) -> 791.2381 | F18: =IFERROR(F4/(12*$B4),0) -> 791.2381 | G18: =IFERROR(G4/(12*$B4),0) -> 791.2381 | H18: =IFERROR(H4/(12*$B4),0) -> 791.2381 | I18: =IFERROR(I4/(12*$B4),0) -> 791.2381 | J18: =IFERROR(J4/(12*$B4),0) -> 791.2381 | K18: =IFERROR(K4/(12*$B4),0) -> 791.2381 | ... CA18: =IFERROR(CA4/(12*$B4),0) -> 791.2381
A19: SEA RAY 34 SUNDANCER | C19: 6190.47 | D19: =IFERROR(D5/(12*$B5),0) -> 773.80952 | E19: =IFERROR(E5/(12*$B5),0) -> 773.80952 | F19: =IFERROR(F5/(12*$B5),0) -> 773.80952 | G19: =IFERROR(G5/(12*$B5),0) -> 773.80952 | H19: =IFERROR(H5/(12*$B5),0) -> 773.80952 | I19: =IFERROR(I5/(12*$B5),0) -> 773.80952 | J19: =IFERROR(J5/(12*$B5),0) -> 773.80952 | K19: =IFERROR(K5/(12*$B5),0) -> 773.80952 | ... EQ19: =IFERROR(EQ5/(12*$B5),0) -> 0
A20: PACIFIC BOAT CLUB FLEET | D20: =IFERROR(D6/(12*$B6),0) -> 0 | E20: =IFERROR(E6/(12*$B6),0) -> 0 | F20: =IFERROR(F6/(12*$B6),0) -> 0 | G20: =IFERROR(G6/(12*$B6),0) -> 0 | H20: =IFERROR(H6/(12*$B6),0) -> 1785.7143 | I20: =IFERROR(I6/(12*$B6),0) -> 1785.7143 | J20: =IFERROR(J6/(12*$B6),0) -> 1785.7143 | K20: =IFERROR(K6/(12*$B6),0) -> 1785.7143 | ... T20: =IFERROR(T6/(12*$B6),0) -> 1785.7143 | U20: =IFERROR(U6/(12*$B6),0)+381.77 -> 1785.7105 | V20: =IFERROR(V6/(12*$B6),0) -> 1403.9405 | W20: =IFERROR(W6/(12*$B6),0) -> 1403.9405 | X20: =IFERROR(X6/(12*$B6),0)+329.14 -> 1403.9376 | Y20: =IFERROR(Y6/(12*$B6),0) -> 1074.7976 | Z20: =IFERROR(Z6/(12*$B6),0) -> 1074.7976 | AA20: =IFERROR(AA6/(12*$B6),0) -> 1074.7976 | AB20: =IFERROR(AB6/(12*$B6),0) -> 1074.7976 | AC20: =IFERROR(AC6/(12*$B6),0) -> 1074.7976 | AD20: =IFERROR(AD6/(12*$B6),0) -> 1074.7976 | AE20: =IFERROR(AE6/(12*$B6),0) -> 1074.7976 | AF20: =IFERROR(AF6/(12*$B6),0) -> 1074.7976 | ... AO20: =IFERROR(AO6/(12*$B6),0) -> 1074.7976 | AP20: 1074.8 | AQ20: 902.82 | AR20: 902.82 | AS20: 902.82 | AT20: 902.82 | AU20: 902.82 | AV20: 902.82 | AW20: 902.82 | AX20: 902.82 | AY20: 902.82 | AZ20: 902.82 | BA20: 902.82 | BB20: 902.82 | BC20: 902.82 | BD20: 902.82 | BE20: 902.82 | BF20: 902.82 | BG20: 902.82 | BH20: 902.82 | BI20: 902.82 | BJ20: 902.82 | BK20: 902.82 | BL20: 902.82 | BM20: 902.82 | BN20: 902.82 | BO20: 902.82 | BP20: 902.82 | BQ20: 902.82 | BR20: 902.82 | BS20: 902.82 | BT20: 902.82 | BU20: 902.82 | BV20: 902.82 | BW20: 902.82 | BX20: 902.82 | BY20: 902.82 | BZ20: 902.82 | CA20: 902.82 | CB20: 902.82 | CC20: 902.82 | CD20: 902.82 | CE20: 902.82 | CF20: 902.82 | CG20: 902.82 | CH20: 902.82 | CI20: 902.82 | CJ20: 902.82 | CK20: 902.82 | CL20: 902.82 | CM20: 902.82
A21: BENETEAU FLYER 9 | D21: =IFERROR(D7/(12*$B7),0) -> 0 | E21: =IFERROR(E7/(12*$B7),0) -> 0 | F21: =IFERROR(F7/(12*$B7),0) -> 0 | G21: =IFERROR(G7/(12*$B7),0) -> 0 | H21: =IFERROR(H7/(12*$B7),0) -> 0 | I21: =IFERROR(I7/(12*$B7),0) -> 3142.7712 | J21: =IFERROR(J7/(12*$B7),0) -> 3142.7712 | K21: =IFERROR(K7/(12*$B7),0) -> 3142.7712 | ... CN21: =IFERROR(CN7/(12*$B7),0) -> 3142.7712
A22: AXOPAR SUNTOP 37 | D22: =IFERROR(D8/(12*$B8),0) -> 0 | E22: =IFERROR(E8/(12*$B8),0) -> 0 | F22: =IFERROR(F8/(12*$B8),0) -> 0 | G22: =IFERROR(G8/(12*$B8),0) -> 0 | H22: =IFERROR(H8/(12*$B8),0) -> 0 | I22: =IFERROR(I8/(12*$B8),0) -> 0 | J22: =IFERROR(J8/(12*$B8),0) -> 3213.0952 | K22: =IFERROR(K8/(12*$B8),0) -> 3213.0952 | ... CO22: =IFERROR(CO8/(12*$B8),0) -> 3213.0952
A23: Axopar T-Top 28 | D23: =IFERROR(D9/(12*$B9),0) -> 0 | E23: =IFERROR(E9/(12*$B9),0) -> 0 | F23: =IFERROR(F9/(12*$B9),0) -> 0 | G23: =IFERROR(G9/(12*$B9),0) -> 0 | H23: =IFERROR(H9/(12*$B9),0) -> 0 | I23: =IFERROR(I9/(12*$B9),0) -> 0 | J23: =IFERROR(J9/(12*$B9),0) -> 0 | K23: =IFERROR(K9/(12*$B9),0) -> 0 | ... DE23: =IFERROR(DE9/(12*$B9),0) -> 1666.6667
A24: NX 340 Sport Cruisr | D24: =IFERROR(D10/(12*$B10),0) -> 0 | E24: =IFERROR(E10/(12*$B10),0) -> 0 | F24: =IFERROR(F10/(12*$B10),0) -> 0 | G24: =IFERROR(G10/(12*$B10),0) -> 0 | H24: =IFERROR(H10/(12*$B10),0) -> 0 | J24: =IFERROR(J10/(12*$B10),0) -> 0 | K24: =IFERROR(K10/(12*$B10),0) -> 0 | L24: =IFERROR(L10/(12*$B10),0) -> 0 | M24: =IFERROR(M10/(12*$B10),0) -> 0 | N24: =IFERROR(N10/(12*$B10),0) -> 0 | O24: =IFERROR(O10/(12*$B10),0) -> 0 | P24: =IFERROR(P10/(12*$B10),0) -> 0 | Q24: =IFERROR(Q10/(12*$B10),0) -> 0 | ... DE24: =IFERROR(DE10/(12*$B10),0) -> 3247.0774
A28: Total Depreciation | C28: =SUM(C18:C27) -> 12520.378 | D28: =SUM(D18:D27) -> 1565.0476 | E28: =SUM(E18:E27) -> 1565.0476 | F28: =SUM(F18:F27) -> 1565.0476 | G28: =SUM(G18:G27) -> 1565.0476 | H28: =SUM(H18:H27) -> 3350.7619 | I28: =SUM(I18:I27) -> 6493.5331 | J28: =SUM(J18:J27) -> 9706.6283 | ... EQ28: =SUM(EQ18:EQ27) -> 0
X30: =W20-X20 -> 0.0028571429
A31: Acc Depreciation
C33: =C17 -> 44439 | D33: =EOMONTH(C33,1) -> 44469 | E33: =EOMONTH(D33,1) -> 44500 | F33: =EOMONTH(E33,1) -> 44530 | G33: =EOMONTH(F33,1) -> 44561 | H33: =EOMONTH(G33,1) -> 44592 | I33: =EOMONTH(H33,1) -> 44620 | J33: =EOMONTH(I33,1) -> 44651 | K33: =EOMONTH(J33,1) -> 44681 | ... EQ33: =EOMONTH(EP33,1) -> 48822
A34: MANITOU 25 OASIS | C34: =C18+B34 -> 6329.9081 | D34: =D18+C34 -> 7121.1462 | E34: =E18+D34 -> 7912.3843 | F34: =F18+E34 -> 8703.6224 | G34: =G18+F34 -> 9494.8605 | H34: =H18+G34 -> 10286.099 | I34: =I18+H34 -> 11077.337 | J34: =J18+I34 -> 11868.575 | ... EQ34: =EQ18+EP34 -> 66464.003
A35: SEA RAY 34 SUNDANCER | C35: =C19+B35 -> 6190.47 | D35: =D19+C35 -> 6964.2795 | E35: =E19+D35 -> 7738.089 | F35: =F19+E35 -> 8511.8986 | G35: =G19+F35 -> 9285.7081 | H35: =H19+G35 -> 10059.518 | I35: =I19+H35 -> 10833.327 | J35: =J19+I35 -> 11607.137 | ... AJ35: =AJ19+AI35 -> 31726.184
A36: PACIFIC BOAT CLUB FLEET | C36: =C20+B36 -> 0 | D36: =D20+C36 -> 0 | E36: =E20+D36 -> 0 | F36: =F20+E36 -> 0 | G36: =G20+F36 -> 0 | H36: =H20+G36 -> 1785.7143 | I36: =I20+H36 -> 3571.4286 | J36: =J20+I36 -> 5357.1429 | ... T36: =T20+S36 -> 23214.286 | U36: =U20+T36-3869.05 -> 21130.946 | V36: =V20+U36 -> 22534.887 | W36: =W20+V36 -> 23938.827 | X36: =X20+W36-5595.43-1475.78 -> 18271.555 | Y36: =Y20+X36 -> 19346.352 | Z36: =Z20+Y36 -> 20421.15 | AA36: =AA20+Z36 -> 21495.948 | AB36: =AB20+AA36 -> 22570.745 | AC36: =AC20+AB36 -> 23645.543 | AD36: =AD20+AC36 -> 24720.34 | AE36: =AE20+AD36 -> 25795.138 | AF36: =AF20+AE36 -> 26869.936 | ... AO36: =AO20+AN36 -> 36543.114 | AP36: =AP20+AO36-9193.05 -> 28424.864 | AQ36: =AQ20+AP36 -> 29327.684 | AR36: =AR20+AQ36 -> 30230.504 | AS36: =AS20+AR36 -> 31133.324 | AT36: =AT20+AS36 -> 32036.144 | AU36: =AU20+AT36 -> 32938.964 | AV36: =AV20+AU36 -> 33841.784 | AW36: =AW20+AV36 -> 34744.604 | AX36: =AX20+AW36 -> 35647.424 | ... EQ36: =EQ20+EP36 -> 72663.044
A37: BENETEAU FLYER 9 | C37: =C21+B37 -> 0 | D37: =D21+C37 -> 0 | E37: =E21+D37 -> 0 | F37: =F21+E37 -> 0 | G37: =G21+F37 -> 0 | H37: =H21+G37 -> 0 | I37: =I21+H37 -> 3142.7712 | J37: =J21+I37 -> 6285.5424 | ... EQ37: =EQ21+EP37 -> 263992.78
A38: AXOPAR SUNTOP 37 | C38: =C22+B38 -> 0 | D38: =D22+C38 -> 0 | E38: =E22+D38 -> 0 | F38: =F22+E38 -> 0 | G38: =G22+F38 -> 0 | H38: =H22+G38 -> 0 | I38: =I22+H38 -> 0 | J38: =J22+I38 -> 3213.0952 | ... EQ38: =EQ22+EP38 -> 269900
A39: Axopar T-Top 28 | C39: =C23+B39 -> 0 | D39: =D23+C39 -> 0 | E39: =E23+D39 -> 0 | F39: =F23+E39 -> 0 | G39: =G23+F39 -> 0 | H39: =H23+G39 -> 0 | I39: =I23+H39 -> 0 | J39: =J23+I39 -> 0 | ... EQ39: =EQ23+EP39 -> 140000
A40: NX 340 Sport Cruisr | C40: =C24+B40 -> 0 | D40: =D24+C40 -> 0 | E40: =E24+D40 -> 0 | F40: =F24+E40 -> 0 | G40: =G24+F40 -> 0 | H40: =H24+G40 -> 0 | I40: =I24+H40 -> 0 | J40: =J24+I40 -> 0 | ... EQ40: =EQ24+EP40 -> 272754.5
A43: Total Depreciation | C43: =SUM(C34:C40) -> 12520.378 | D43: =SUM(D34:D40) -> 14085.426 | E43: =SUM(E34:E40) -> 15650.473 | F43: =SUM(F34:F40) -> 17215.521 | G43: =SUM(G34:G40) -> 18780.569 | H43: =SUM(H34:H40) -> 22131.33 | I43: =SUM(I34:I40) -> 28624.864 | J43: =SUM(J34:J40) -> 38331.492 | ... EQ43: =SUM(EQ34:EQ40) -> 1085774.3
A46: NBV
C48: =C33 -> 44439 | D48: =EOMONTH(C48,1) -> 44469 | E48: =EOMONTH(D48,1) -> 44500 | F48: =EOMONTH(E48,1) -> 44530 | G48: =EOMONTH(F48,1) -> 44561 | H48: =EOMONTH(G48,1) -> 44592 | I48: =EOMONTH(H48,1) -> 44620 | J48: =EOMONTH(I48,1) -> 44651 | K48: =EOMONTH(J48,1) -> 44681 | ... EQ48: =EOMONTH(EP48,1) -> 48822
A49: MANITOU 25 OASIS | C49: =C4-C34 -> 60134.092 | D49: =D4-D34 -> 59342.854 | E49: =E4-E34 -> 58551.616 | F49: =F4-F34 -> 57760.378 | G49: =G4-G34 -> 56969.14 | H49: =H4-H34 -> 56177.901 | I49: =I4-I34 -> 55386.663 | J49: =J4-J34 -> 54595.425 | ... EQ49: =EQ4-EQ34 -> -0.0033333332
A50: SEA RAY 34 SUNDANCER | C50: =C5-C35 -> 58809.53 | D50: =D5-D35 -> 58035.72 | E50: =E5-E35 -> 57261.911 | F50: =F5-F35 -> 56488.101 | G50: =G5-G35 -> 55714.292 | H50: =H5-H35 -> 54940.482 | I50: =I5-I35 -> 54166.673 | J50: =J5-J35 -> 53392.863 | ... EQ50: =EQ5-EQ35 -> 0
A51: PACIFIC BOAT CLUB FLEET | C51: =C6-C36 -> 0 | D51: =D6-D36 -> 0 | E51: =E6-E36 -> 0 | F51: =F6-F36 -> 0 | G51: =G6-G36 -> 0 | H51: =H6-H36 -> 148214.29 | I51: =I6-I36 -> 146428.57 | J51: =J6-J36 -> 144642.86 | ... EQ51: =EQ6-EQ36 -> -4443.3543
A52: BENETEAU FLYER 9 | C52: =C7-C37 -> 0 | D52: =D7-D37 -> 0 | E52: =E7-E37 -> 0 | F52: =F7-F37 -> 0 | G52: =G7-G37 -> 0 | H52: =H7-H37 -> 0 | I52: =I7-I37 -> 260850.01 | J52: =J7-J37 -> 257707.24 | ... EQ52: =EQ7-EQ37 -> 0
A53: AXOPAR SUNTOP 37 | C53: =C8-C38 -> 0 | D53: =D8-D38 -> 0 | E53: =E8-E38 -> 0 | F53: =F8-F38 -> 0 | G53: =G8-G38 -> 0 | H53: =H8-H38 -> 0 | I53: =I8-I38 -> 0 | J53: =J8-J38 -> 266686.9 | ... EQ53: =EQ8-EQ38 -> 0
A54: Axopar T-Top 28 | C54: =C9-C39 -> 0 | D54: =D9-D39 -> 0 | E54: =E9-E39 -> 0 | F54: =F9-F39 -> 0 | G54: =G9-G39 -> 0 | H54: =H9-H39 -> 0 | I54: =I9-I39 -> 0 | J54: =J9-J39 -> 0 | ... EQ54: =EQ9-EQ39 -> 0
A55: NX 340 Sport Cruisr | C55: =C10-C40 -> 0 | D55: =D10-D40 -> 0 | E55: =E10-E40 -> 0 | F55: =F10-F40 -> 0 | G55: =G10-G40 -> 0 | H55: =H10-H40 -> 0 | I55: =I10-I40 -> 0 | J55: =J10-J40 -> 0 | ... EQ55: =EQ10-EQ40 -> 5.8207661e-10
...

Sheet 17000 - Goodwill
A1: Goodwill
A3: Amount | B3: 174500
B4: =15*12 -> 180
A5: Monthly Amortiz | B5: =B3/B4 -> 969.44444
A6: Accumulated Amortiz | B6: =-SUM(B8:B47) -> 38760 | C6: ENDING BALANCE | D6: ACCUM AMORT
C7: =B3 -> 174500
A8: 44409 | B8: -969 | C8: =C7+B8 -> 173531 | D8: =-B8 -> 969
A9: 44440 | B9: -969 | C9: =C8+B9 -> 172562 | D9: =D8-B9 -> 1938
A10: 44470 | B10: -969 | C10: =C9+B10 -> 171593 | D10: =D9-B10 -> 2907
A11: 44501 | B11: -969 | C11: =C10+B11 -> 170624 | D11: =D10-B11 -> 3876
A12: 44531 | B12: -969 | C12: =C11+B12 -> 169655 | D12: =D11-B12 -> 4845
A13: 44562 | B13: -969 | C13: =C12+B13 -> 168686 | D13: =D12-B13 -> 5814
A14: 44593 | B14: -969 | C14: =C13+B14 -> 167717 | D14: =D13-B14 -> 6783
A15: 44621 | B15: -969 | C15: =C14+B15 -> 166748 | D15: =D14-B15 -> 7752
A16: 44652 | B16: -969 | C16: =C15+B16 -> 165779 | D16: =D15-B16 -> 8721
A17: 44682 | B17: -969 | C17: =C16+B17 -> 164810 | D17: =D16-B17 -> 9690
A18: 44713 | B18: -969 | C18: =C17+B18 -> 163841 | D18: =D17-B18 -> 10659
A19: 44743 | B19: -969 | C19: =C18+B19 -> 162872 | D19: =D18-B19 -> 11628
A20: 44774 | B20: -969 | C20: =C19+B20 -> 161903 | D20: =D19-B20 -> 12597
... A48: 45657 | B48: -969 | C48: =C47+B48 -> 134771 | D48: =D47-B48 -> 39729
A49: =EOMONTH(A48,1) -> 45688 | B49: -969 | C49: =C48+B49 -> 133802 | D49: =D48-B49 -> 40698
A50: =EOMONTH(A49,1) -> 45716 | B50: -969 | C50: =C49+B50 -> 132833 | D50: =D49-B50 -> 41667
A51: =EOMONTH(A50,1) -> 45747 | B51: -969 | C51: =C50+B51 -> 131864 | D51: =D50-B51 -> 42636
A52: =EOMONTH(A51,1) -> 45777 | B52: -969 | C52: =C51+B52 -> 130895 | D52: =D51-B52 -> 43605
A53: =EOMONTH(A52,1) -> 45808 | B53: -969 | C53: =C52+B53 -> 129926 | D53: =D52-B53 -> 44574
A54: =EOMONTH(A53,1) -> 45838 | B54: -969 | C54: =C53+B54 -> 128957 | D54: =D53-B54 -> 45543
A55: =EOMONTH(A54,1) -> 45869 | B55: -969 | C55: =C54+B55 -> 127988 | D55: =D54-B55 -> 46512
A56: =EOMONTH(A55,1) -> 45900 | B56: -969 | C56: =C55+B56 -> 127019 | D56: =D55-B56 -> 47481
A57: =EOMONTH(A56,1) -> 45930 | B57: -969 | C57: =C56+B57 -> 126050 | D57: =D56-B57 -> 48450
A58: =EOMONTH(A57,1) -> 45961 | B58: -969 | C58: =C57+B58 -> 125081 | D58: =D57-B58 -> 49419
A59: =EOMONTH(A58,1) -> 45991 | B59: -969 | C59: =C58+B59 -> 124112 | D59: =D58-B59 -> 50388
A60: =EOMONTH(A59,1) -> 46022 | B60: -969 | C60: =C59+B60 -> 123143 | D60: =D59-B60 -> 51357
... A187: =EOMONTH(A186,1) -> 49887 | B187: -969 | C187: =C186+B187 -> 80 | D187: =D186-B187 -> 174420

Sheet 21000 - Accrued Expenses
A1: Accrued Exp
A4: Vendor | B4: Adj T/B | C4: GL Date | D4: Period | E4: Accrued | F4: Date Paid | G4: Paid | H4: Remaining | I4: Notes
A5: Sales Commission | B5: 12186.5 | C5: 45657 | D5: 45657 | E5: =SUM('Sales commission detail'!I2:I20) -> 12186.5 | G5: 12186.5 | H5: =E5-G5 -> 0
A6: Sales Commission | B6: 609 | C6: 45688 | D6: 45688 | E6: ='Sales commission detail'!I21 -> 609 | G6: 609 | H6: =E6-G6 -> 0
A7: Sales Commission | B7: 174.75 | C7: 45688 | D7: 45688 | E7: =B7 -> 174.75 | H7: =E7-G7 -> 174.75
A8: ADP | B8: 468.66 | C8: 45716 | D8: 45716 | E8: =B8 -> 468.66 | F8: 45768 | G8: 468.66 | H8: =E8-G8 -> 0
A9: ADP | B9: 468.66 | C9: 45747 | D9: 45747 | E9: =B9 -> 468.66 | G9: 468.66 | H9: =E9-G9 -> 0
A10: ADP | B10: 468.66 | C10: 45777 | D10: 45777 | E10: =B10 -> 468.66 | G10: 468.66 | H10: =E10-G10 -> 0
A11: Sales Commission | B11: 2375 | C11: 45777 | D11: 45777 | E11: =B11 -> 2375 | H11: =E11-G11 -> 2375
A12: Sales Commission | B12: 600 | C12: 45808 | D12: 45808 | E12: =B12 -> 600 | H12: =E12-G12 -> 600
A13: ADP | B13: 468.66 | C13: 45808 | D13: 45808 | E13: =B13 -> 468.66 | G13: 468.66 | H13: =E13-G13 -> 0
A14: ADP | B14: 468.66 | C14: 45838 | D14: 45838 | E14: =B14 -> 468.66 | F14: 45887 | G14: 468.66 | H14: =E14-G14 -> 0
A15: ADP Tax | B15: 649.59 | E15: =B15 -> 649.59 | G15: 649.59 | H15: =E15-G15 -> 0
A16: STATE COMP | B16: 456.25 | C16: 45869 | D16: 45930 | E16: =B16 -> 456.25 | G16: 456.25 | H16: =E16-G16 -> 0
A17: ADP | B17: 468.66 | C17: 45869 | D17: 45869 | E17: =B17 -> 468.66 | G17: 468.66 | H17: =E17-G17 -> 0
A18: ADP | B18: 468.66 | C18: 45900 | D18: 45900 | E18: =B18 -> 468.66 | G18: 468.66 | H18: =E18-G18 -> 0
A19: ADP | B19: 468.66 | C19: 45930 | D19: 45930 | E19: =B19 -> 468.66 | G19: 468.66 | H19: =E19-G19 -> 0 | I19: reversed all ADP fees
A20: ADP | B20: 468.66 | C20: 45961 | D20: 45961 | E20: =B20 -> 468.66 | G20: 468.66 | H20: =E20-G20 -> 0 | I20: reversed all ADP fees
A21: ADP | B21: 468.66 | C21: 45991 | D21: 45991 | E21: =B21 -> 468.66 | G21: 468.66 | H21: =E21-G21 -> 0 | I21: reversed all ADP fees
H22: =E22-G22 -> 0 | I22: No sales commission in the master sheet for December
A23: Total | B23: =SUM(B5:B12) -> 17351.23 | G23: Prepaid Total | H23: =SUM(H5:H22) -> 3149.75
G25: GL Total | H25: 3149.75
G26: Difference | H26: =H23-H25 -> 0

Sheet Sheet1

Sheet Sales commission detail
A1: Date Sold | B1: Customer name | C1: initiation | D1: commission due | E1: Salesperson | F1: Commission % (Determined by monthly sales volume | G1: Ryan commishpaid | H1: peter and carlos
A2: 45295 | B2: Leon Weathersby and Lauren Hobb | C2: 8500 | D2: 850 | E2: carlos/peter | F2: 0.1 | G2: paid or NA | H2: UNPAID | I2: =D2 -> 850
A3: 45299 | B3: David Durant and Omar Othman | C3: 12250 | D3: 1225 | E3: carlos/peter | F3: 0.1 | G3: paid or NA | H3: UNPAID | I3: 1225
A4: 45301 | B4: Brian Walrod and Skip kingery | C4: 19000 | D4: 1900 | E4: Carlos/peter | F4: 0.1 | G4: paid or NA | H4: UNPAID | I4: 1900
A5: 45340 | B5: Scott Dixon | C5: 12250 | D5: 1250 | E5: Ryan | F5: 0.1 | G5: paid or NA | I5: 0
A6: 45390 | B6: Joe Faruqui | C6: 20000 | D6: 1000 | E6: Ryan | F6: 0.05 | G6: paid or NA | I6: 0
A7: 45392 | B7: Autumn Lemon | C7: 12500 | D7: 625 | E7: Ryan | F7: 0.05 | G7: paid or NA | I7: 0
A8: 45444 | B8: Scott Javore | C8: 8000 | D8: 800 | E8: Peter Carlos | F8: 0.1 | G8: paid or NA | H8: UNPAID | I8: 800
A9: 45426 | B9: Ken Fait and Jimmy Sabatino | C9: 24500 | D9: 1225 | E9: Ryan referral | F9: 0.05 | G9: 1225 | I9: 0
A10: 45444 | B10: Bruce and Jackie Gulbas | C10: 22500 | D10: 2250 | E10: Split | F10: 0.1 | G10: 1125 | H10: UNPAID | I10: 1125
A11: 45792 | B11: Dave Groth/Ralph Dion half membership paired with Adrian Heffernan | C11: 11000 | D11: 1100 | E11: Split | F11: 0.1 | G11: 550 | H11: UNPAID | I11: 550
A12: 45432 | B12: Adrian and Meghan Heffernan | C12: 12250 | D12: 1225 | E12: Carlos Peter | F12: 0.1 | H12: UNPAID | I12: 1225
A13: 45435 | B13: Blake Bollen and John Bollen (needs second half filled) | C13: 11360 | D13: 1136 | E13: Split | F13: 0.1 | G13: 568 | H13: UNPAID | I13: 568
A14: 45444 | B14: West Capital Lending CORPORATE (Daniel, Eric, Tony, Amir) | C14: 26000 | D14: 1300 | E14: Ryan referral | F14: 0.05 | G14: 1300 | I14: 0
A15: 45466 | B15: Nik Kafetzopoulos | C15: 10500 | D15: 1050 | E15: Peter/Carlos | F15: 0.1 | H15: UNPAID | I15: 1050
A16: 45474 | B16: Eric Dall | C16: 12000 | D16: 1200 | E16: Peter/Carlos | F16: 0.1 | H16: UNPAID | I16: 1200
A17: 45589 | B17: Joe DeCosta (half yacht paired with Finke) | C17: 3045 | D17: 304.5 | E17: Peter/Carlos | F17: 0.1 | H17: UNPAID | I17: 304.5
A18: 45594 | B18: David and Eric Finke (paired w Joe decosta) | C18: 3495 | D18: 349.5 | E18: Peter/Carlos | F18: 0.1 | H18: UNPAID | I18: 349.5
A19: 45597 | B19: Jack Biehl (half yacht needs partner) | C19: 3495 | D19: 349.5 | E19: Peter/Carlos | F19: 0.1 | H19: UNPAID | I19: 349.5
A20: 45597 | B20: Blake Andrew and Geoff | C20: 6900 | D20: 690 | E20: Peter/Carlos | F20: 0.1 | H20: UNPAID | I20: 690
A21: 1/17/2025 | B21: Ray and Brooke Wood | C21: $6,090.00 | D21: $609.00 | E21: Split | F21: 0.1 | G21: 609 | H21: UNPAID | I21: 609
A22: 45741 | B22: Ehsan Sadri (partnered with Jack Biehl) | C22: 3495 | D22: 349.5 | E22: Split | F22: 0.1 | H22: 174.75 | I22: =H22 -> 174.75
A23: 45750 | B23: Megan Brenner (paired with Sarah Sibia) | C23: 11500 | D23: 1150 | E23: Carlos | F23: 0.1 | H23: 1150
A24: 45750 | B24: Sarah Sibia (paired with Megan Brenner) | C24: 11500 | D24: 1150 | E24: Split | F24: 0.1 | H24: 575
A25: 45753 | B25: Marco Vezjak | C25: 5000 | D25: 500 | E25: Split | F25: 0.1 | H25: 250
A26: 45779 | B26: Kyle Dilger (partnered with David and Omar) | C26: 12000 | D26: 1200 | E26: Split w Ryan | F26: 0.1 | H26: 600
A27: 45768 | B27: Larry Davis | C27: 12250 | D27: 1225 | E27: 3 way split | F27: 0.1 | H27: 400
E32: =D27*0.1 -> 122.5 | I32: =SUM(I2:I22) -> 12970.25

Sheet 21050 - Accrued Interest
A1: Name | B1: Beg Balance | C1: interest | D1: payment | E1: ending balance
A2: Manitou Boat | B2: 0.00049864309 | C2: 0 | D2: 0 | E2: =SUM(B2:D2) -> 0.00049864309
A3: Scott Tiernan | B3: 346.74543 | C3: ='22150 & 23150 - Scott Tiernan'!E61 -> 21.124206 | E3: =SUM(B3:D3) -> 367.86964
A4: CCJ True Loan 2 | B4: 861.57436 | C4: ='23400 - CCJ True Loan (2)'!E18 -> 426.31218 | D4: =-'23400 - CCJ True Loan (2)'!E17-'23400 - CCJ True Loan (2)'!E16 -> -861.57436 | E4: =SUM(B4:D4) -> 426.31218
A5: CCJ True Loan | B5: 2913.5176 | C5: 0 | D5: =-'23350 - CCJ True Loan'!E17 -> -2913.5176 | E5: =SUM(B5:D5) -> 0
B6: 0 | E6: =SUM(B6:D6) -> 0
B7: 0 | E7: =SUM(B7:D7) -> 0
A8: Total | B8: =SUM(B2:B7) -> 4121.8379 | E8: =SUM(E2:E7) -> 794.18231
A9: Sitting in G/L | B9: 4121.84 | E9: 794.17
A10: Difference | B10: =B8-B9 -> -0.0020708486 | E10: =E8-E9 -> 0.012310814

Sheet 21100 - Accrued Payroll
A1: PR Accrual
A2: PR End Date | B2: 46007
A3: Month End Date | B3: 46022 | C3: 0 | P3: =5000+567.36+951.3+500 -> 7018.66
A5: Outstanding Days | B5: =NETWORKDAYS(B2+2,B3,0) -> 10 | I5: OFFICER PAYROLL NOT PAID OUT
A6: Total Payroll | B6: 0 | I6: DATE | J6: AMOUNT
A7: Payroll Days | B7: 10 | I7: JANUARY | J7: 5562.5 | K7: =2500 -> 2500 | M7: =J7-5000 -> 562.5
A8: Pay per day | B8: =B6/B7 -> 0 | I8: FEBRUARY | J8: 5382.5 | K8: =K7 -> 2500 | M8: =J8-5000 -> 382.5
A9: Salaries Accrual | B9: =B8*B5 -> 0 | I9: MARCH | J9: 5382.5 | K9: =K8 -> 2500 | M9: =J9-5000 -> 382.5
I10: APRIL | J10: 5382.5 | K10: =K9 -> 2500 | M10: =J10-5000 -> 382.5
A11: Total Taxes | B11: 0 | C11: *Employer taxes only | I11: OCTOBER | J11: 5267.76 | K11: =K10 -> 2500 | M11: =J11-5000 -> 267.76
A12: Pay per day | B12: =B11/B7 -> 0 | I12: NOVEMBER | J12: 5267.76 | K12: =K11 -> 2500 | M12: =J12-5000 -> 267.76
A13: Taxes Accrual | B13: =B5*B12 -> 0
I14: PAID IN APRIL | J14: -30000 | K14: =SUM(K7:K13) -> 15000
A15: 1099 Payroll | B15: 6602.33 | I15: JUNE PETER NOT PAID | J15: =SUM(K15,M15) -> 2691.25 | K15: 2500 | M15: 191.25
A16: Payroll Days | B16: 10 | I16: PAID IN JULY | J16: =-J15 -> -2691.25 | M16: =-M15 -> -191.25
A17: Pay per day | B17: =B15/B16 -> 660.233
A18: 1099 Accrual | B18: =B17*B5 -> 6602.33
A20: COMMISSION | B20: 0
J21: =SUM(J7:J20) -> 2245.52 | L21: Employer taxes | M21: =SUM(M7:M20) -> 2245.52
A22: ACCRUAL | B22: =SUM(B9,B13,B18,B20) -> 6602.33
A23: Bonus
A25: Total Payroll Accrual | B25: =B9+B13+B18+B20+B23 -> 6602.33
A26: Undeposited Checks | B26: 1100 | C26: manual payment to Javier Osores
A27: Undeposited Checks | B27: 228.48 | C27: Manual Check # 902 for Preston, Bond
A31: Total Payroll Accrual | B31: =SUM(B25:B30) -> 7930.81
A34: Officer Wages
A35: Officer Taxes
A36: Officer Commissions

Sheet 21125 - Unearned Revenue
F1: 2021 RECOGNITION | G1: =SUM(E4:E21)-SUM(I4:M21) -> 101459.33
B3: JOIN DATE | C3: MEMBER | D3: DUES | E3: COLLECTED | F3: MONTHLY RECOGNITION | G3: END DATE | I3: 44439 | J3: =EOMONTH(I3,1) -> 44469 | K3: =EOMONTH(J3,1) -> 44500 | L3: =EOMONTH(K3,1) -> 44530 | M3: =EOMONTH(L3,1) -> 44561 | N3: =EOMONTH(M3,1) -> 44592 | O3: =EOMONTH(N3,1) -> 44620 | P3: =EOMONTH(O3,1) -> 44651 | Q3: =EOMONTH(P3,1) -> 44681 | ... DP3: =EOMONTH(DO3,1) -> 47817
A4: =A3+1 -> 1 | B4: 44421 | C4: Michale Kurland and Jerry Jon Thomas | D4: Initiation Fees | E4: 15000 | F4: =E4/60 -> 250 | G4: 46233 | H4: =E4-SUM(I4:DP4) -> 0 | I4: =$F$4 -> 250 | J4: =$F$4 -> 250 | K4: =$F$4 -> 250 | L4: =$F$4 -> 250 | M4: =$F$4 -> 250 | N4: =$F$4 -> 250 | O4: =$F$4 -> 250 | P4: =$F$4 -> 250 | ... BP4: =$F$4 -> 250
A5: =A4+1 -> 2 | B5: 44440 | C5: Greg and Karen Castro | D5: Initiation Fees | E5: 5000 | F5: =E5/60 -> 83.333333 | G5: 46265 | H5: =E5-SUM(I5:DP5) -> 0 | J5: =$F$5 -> 83.333333 | K5: =$F$5 -> 83.333333 | L5: =$F$5 -> 83.333333 | M5: =$F$5 -> 83.333333 | N5: =$F$5 -> 83.333333 | O5: =$F$5 -> 83.333333 | P5: =$F$5 -> 83.333333 | Q5: =$F$5 -> 83.333333 | ... BQ5: =$F$5 -> 83.333333
A6: =A5+1 -> 3 | B6: 44440 | C6: Joe and Maryela Pinkston | D6: Initiation Fees | E6: 5000 | F6: =E6/60 -> 83.333333 | G6: 46265 | H6: =E6-SUM(I6:DP6) -> 0 | J6: =$F$6 -> 83.333333 | K6: =$F$6 -> 83.333333 | L6: =$F$6 -> 83.333333 | M6: =$F$6 -> 83.333333 | N6: =$F$6 -> 83.333333 | O6: =$F$6 -> 83.333333 | P6: =$F$6 -> 83.333333 | Q6: =$F$6 -> 83.333333 | ... BQ6: =$F$6 -> 83.333333
A7: =A6+1 -> 4 | B7: 44440 | C7: J. Paul Kovacs and Karen & George Parmenter | D7: Initiation Fees | E7: 5150 | F7: =E7/60 -> 85.833333 | G7: 46265 | H7: =E7-SUM(I7:DP7) -> 0 | J7: =$F$7 -> 85.833333 | K7: =$F$7 -> 85.833333 | L7: =$F$7 -> 85.833333 | M7: =$F$7 -> 85.833333 | N7: =$F$7 -> 85.833333 | O7: =$F$7 -> 85.833333 | P7: =$F$7 -> 85.833333 | Q7: =$F$7 -> 85.833333 | ... BQ7: =$F$7 -> 85.833333
A8: =A7+1 -> 5 | B8: 44441 | C8: Jack Yao and Mike Chen | D8: Initiation Fees | E8: 6000 | F8: =E8/60 -> 100 | G8: 46265 | H8: =E8-SUM(I8:DP8) -> 0 | J8: =$F$8 -> 100 | K8: =$F$8 -> 100 | L8: =$F$8 -> 100 | M8: =$F$8 -> 100 | N8: =$F$8 -> 100 | O8: =$F$8 -> 100 | P8: =$F$8 -> 100 | Q8: =$F$8 -> 100 | ... BQ8: =$F$8 -> 100
A9: =A8+1 -> 6 | B9: 44444 | C9: Cory Freeman / Rebecca Smith | D9: Initiation Fees | E9: 5000 | F9: =E9/60 -> 83.333333 | G9: 46265 | H9: =E9-SUM(I9:DP9) -> 0 | J9: =$F$9 -> 83.333333 | K9: =$F$9 -> 83.333333 | L9: =$F$9 -> 83.333333 | M9: =$F$9 -> 83.333333 | N9: =$F$9 -> 83.333333 | O9: =$F$9 -> 83.333333 | P9: =$F$9 -> 83.333333 | Q9: =$F$9 -> 83.333333 | ... BQ9: =$F$9 -> 83.333333
A10: =A9+1 -> 7 | B10: 44446 | C10: Sherif El Dabe and Michael Yeung | D10: Initiation Fees | E10: 2575 | F10: =E10/60 -> 42.916667 | G10: 46265 | H10: =E10-SUM(I10:DP10) -> 0 | J10: =$F$10 -> 42.916667 | K10: =$F$10 -> 42.916667 | L10: =$F$10 -> 42.916667 | M10: =$F$10 -> 42.916667 | N10: =$F$10 -> 42.916667 | O10: =$F$10 -> 42.916667 | P10: =$F$10 -> 42.916667 | Q10: =$F$10 -> 42.916667 | ... BQ10: =$F$10 -> 42.916667
A11: =A10+1 -> 8 | B11: 44460 | C11: Andy Stavros and Travis Smith | D11: Initiation Fees | E11: 3605 | F11: =E11/60 -> 60.083333 | G11: 46265 | H11: =E11-SUM(I11:DP11) -> 0 | J11: =$F$11 -> 60.083333 | K11: =$F$11 -> 60.083333 | L11: =$F$11 -> 60.083333 | M11: =$F$11 -> 60.083333 | N11: =$F$11 -> 60.083333 | O11: =$F$11 -> 60.083333 | P11: =$F$11 -> 60.083333 | Q11: =$F$11 -> 60.083333 | ... BQ11: =$F$11 -> 60.083333
A12: =A11+1 -> 9 | B12: 44460 | C12: Andy Stavros and Travis Smith | D12: Monthly Membership Dues | E12: 6798 | F12: =E12/16 -> 424.875 | G12: 44896 | H12: =E12-SUM(I12:DP12) -> 0 | J12: =$F$12 -> 424.875 | K12: =$F$12 -> 424.875 | L12: =$F$12 -> 424.875 | M12: =$F$12 -> 424.875 | N12: =$F$12 -> 424.875 | O12: =$F$12 -> 424.875 | P12: =$F$12 -> 424.875 | Q12: =$F$12 -> 424.875 | ... Y12: =$F$12 -> 424.875
A13: =A12+1 -> 10 | B13: 44460 | C13: Andy Stavros and Travis Smith | D13: Initiation Fees | E13: =7000-3605 -> 3395 | F13: =E13/60 -> 56.583333 | G13: 46265 | H13: =E13-SUM(I13:DP13) -> 0 | J13: =$F$13 -> 56.583333 | K13: =$F$13 -> 56.583333 | L13: =$F$13 -> 56.583333 | M13: =$F$13 -> 56.583333 | N13: =$F$13 -> 56.583333 | O13: =$F$13 -> 56.583333 | P13: =$F$13 -> 56.583333 | Q13: =$F$13 -> 56.583333 | ... BQ13: =$F$13 -> 56.583333
A14: =A13+1 -> 11 | B14: 44460 | C14: Andy Stavros and Travis Smith | D14: Monthly Membership Dues | E14: =10100-3395 -> 6705 | F14: =E14/16 -> 419.0625 | G14: 44896 | H14: =E14-SUM(I14:DP14) -> 0 | J14: =$F$14 -> 419.0625 | K14: =$F$14 -> 419.0625 | L14: =$F$14 -> 419.0625 | M14: =$F$14 -> 419.0625 | N14: =$F$14 -> 419.0625 | O14: =$F$14 -> 419.0625 | P14: =$F$14 -> 419.0625 | Q14: =$F$14 -> 419.0625 | ... Y14: =$F$14 -> 419.0625
A15: =A14+1 -> 12 | B15: 44465 | C15: Sam Kasbar | D15: Initiation Fees | E15: 5150 | F15: =E15/60 -> 85.833333 | G15: 46265 | H15: =E15-SUM(I15:DP15) -> 0 | J15: =$F$15 -> 85.833333 | K15: =$F$15 -> 85.833333 | L15: =$F$15 -> 85.833333 | M15: =$F$15 -> 85.833333 | N15: =$F$15 -> 85.833333 | O15: =$F$15 -> 85.833333 | P15: =$F$15 -> 85.833333 | Q15: =$F$15 -> 85.833333 | ... BQ15: =$F$15 -> 85.833333
A16: =A15+1 -> 13 | B16: 44469 | C16: Dean Miles | D16: Initiation Fees | E16: 6775 | F16: =E16/60 -> 112.91667 | G16: 46265 | H16: =E16-SUM(I16:DP16) -> 0 | J16: =$F$16 -> 112.91667 | K16: =$F$16 -> 112.91667 | L16: =$F$16 -> 112.91667 | M16: =$F$16 -> 112.91667 | N16: =$F$16 -> 112.91667 | O16: =$F$16 -> 112.91667 | P16: =$F$16 -> 112.91667 | Q16: =$F$16 -> 112.91667 | ... BQ16: =$F$16 -> 112.91667
A17: =A16+1 -> 14 | B17: 44470 | C17: Vincent Huang | D17: Initiation Fees | E17: 5150 | F17: =E17/60 -> 85.833333 | G17: 46295 | H17: =E17-SUM(I17:DP17) -> 0 | K17: =$F$17 -> 85.833333 | L17: =$F$17 -> 85.833333 | M17: =$F$17 -> 85.833333 | N17: =$F$17 -> 85.833333 | O17: =$F$17 -> 85.833333 | P17: =$F$17 -> 85.833333 | Q17: =$F$17 -> 85.833333 | R17: =$F$17 -> 85.833333 | ... BR17: =$F$17 -> 85.833333
A18: =A17+1 -> 15 | B18: 44470 | C18: Nany Caruso | D18: Initiation Fees | E18: 2575 | F18: =E18/60 -> 42.916667 | G18: 46295 | H18: =E18-SUM(I18:DP18) -> 0 | K18: =$F$18 -> 42.916667 | L18: =$F$18 -> 42.916667 | M18: =$F$18 -> 42.916667 | N18: =$F$18 -> 42.916667 | O18: =$F$18 -> 42.916667 | P18: =$F$18 -> 42.916667 | Q18: =$F$18 -> 42.916667 | R18: =$F$18 -> 42.916667 | ... BR18: =$F$18 -> 42.916667
A19: =A18+1 -> 16 | B19: 44484 | C19: David Pann and Alex Razo | D19: Initiation Fees | E19: 15000 | F19: =E19/60 -> 250 | G19: 46295 | H19: =E19-SUM(I19:DP19) -> 0 | K19: =$F$19 -> 250 | L19: =$F$19 -> 250 | M19: =$F$19 -> 250 | N19: =$F$19 -> 250 | O19: =$F$19 -> 250 | P19: =$F$19 -> 250 | Q19: =$F$19 -> 250 | R19: =$F$19 -> 250 | ... BR19: =$F$19 -> 250
A20: =A19+1 -> 17 | B20: 44518 | C20: Terri Eisenberg | D20: Initiation Fees | E20: 5000 | F20: =E20/60 -> 83.333333 | G20: 46326 | H20: =E20-SUM(I20:DP20) -> 0 | L20: =$F$20 -> 83.333333 | M20: =$F$20 -> 83.333333 | N20: =$F$20 -> 83.333333 | O20: =$F$20 -> 83.333333 | P20: =$F$20 -> 83.333333 | Q20: =$F$20 -> 83.333333 | R20: =$F$20 -> 83.333333 | S20: =$F$20 -> 83.333333 | ... BS20: =$F$20 -> 83.333333
A21: =A20+1 -> 18 | B21: 44531 | C21: Diyonne and Manny Rojas | D21: Initiation Fees | E21: 6800 | F21: =E21/60 -> 113.33333 | G21: 46356 | H21: =E21-SUM(I21:DP21) -> 0 | M21: =$F$21 -> 113.33333 | N21: =$F$21 -> 113.33333 | O21: =$F$21 -> 113.33333 | P21: =$F$21 -> 113.33333 | Q21: =$F$21 -> 113.33333 | R21: =$F$21 -> 113.33333 | S21: =$F$21 -> 113.33333 | T21: =$F$21 -> 113.33333 | ... BT21: =$F$21 -> 113.33333
A22: =A21+1 -> 19 | B22: 44585 | C22: Robert LaMattina | D22: Initiation Fees | E22: 15000 | F22: =E22/60 -> 250 | G22: 46387 | H22: =E22-SUM(I22:DP22) -> 0 | N22: =$F$22 -> 250 | O22: =$F$22 -> 250 | P22: =$F$22 -> 250 | Q22: =$F$22 -> 250 | R22: =$F$22 -> 250 | S22: =$F$22 -> 250 | T22: =$F$22 -> 250 | U22: =$F$22 -> 250 | ... BU22: =$F$22 -> 250
A23: =A22+1 -> 20 | B23: 44621 | C23: Nathan and Renee Linder | D23: Initiation Fees | E23: 15000 | F23: =E23/60 -> 250 | G23: 46418 | H23: =E23-SUM(I23:DP23) -> 0 | O23: =$F$23 -> 250 | P23: =$F$23 -> 250 | Q23: =$F$23 -> 250 | R23: =$F$23 -> 250 | S23: =$F$23 -> 250 | T23: =$F$23 -> 250 | U23: =$F$23 -> 250 | V23: =$F$23 -> 250 | ... BV23: =$F$23 -> 250
A24: =A23+1 -> 21 | B24: 44621 | C24: Jeff Schaffer, David McReynolds | D24: Initiation Fees | E24: 11333 | F24: =E24/60 -> 188.88333 | G24: 46446 | H24: =E24-SUM(I24:DP24) -> 0 | P24: =$F$24 -> 188.88333 | Q24: =$F$24 -> 188.88333 | R24: =$F$24 -> 188.88333 | S24: =$F$24 -> 188.88333 | T24: =$F$24 -> 188.88333 | U24: =$F$24 -> 188.88333 | V24: =$F$24 -> 188.88333 | W24: =$F$24 -> 188.88333 | ... BW24: =$F$24 -> 188.88333
A25: =A24+1 -> 22 | B25: 44621 | C25: Andy Peters | D25: Initiation Fees | E25: 5667 | F25: =E25/60 -> 94.45 | G25: 46446 | H25: =E25-SUM(I25:DP25) -> 0 | P25: =$F$25 -> 94.45 | Q25: =$F$25 -> 94.45 | R25: =$F$25 -> 94.45 | S25: =$F$25 -> 94.45 | T25: =$F$25 -> 94.45 | U25: =$F$25 -> 94.45 | V25: =$F$25 -> 94.45 | W25: =$F$25 -> 94.45 | ... BW25: =$F$25 -> 94.45
A26: =A25+1 -> 23 | B26: 44644 | C26: Jeff and Wendy Azevedo | D26: Initiation Fees | E26: 15000 | F26: =E26/60 -> 250 | G26: 46446 | H26: =E26-SUM(I26:DP26) -> 0 | P26: =$F$26 -> 250 | Q26: =$F$26 -> 250 | R26: =$F$26 -> 250 | S26: =$F$26 -> 250 | T26: =$F$26 -> 250 | U26: =$F$26 -> 250 | V26: =$F$26 -> 250 | W26: =$F$26 -> 250 | ... BW26: =$F$26 -> 250
A27: =A26+1 -> 24 | B27: 44644 | C27: Gary and Laura McArdell | D27: Monthly Membership Dues | E27: 11000 | F27: =E27/12 -> 916.66667 | G27: 44985 | H27: =E27-SUM(I27:DP27) -> 0 | P27: =$F$27 -> 916.66667 | Q27: =$F$27 -> 916.66667 | R27: =$F$27 -> 916.66667 | S27: =$F$27 -> 916.66667 | T27: =$F$27 -> 916.66667 | U27: =$F$27 -> 916.66667 | V27: =$F$27 -> 916.66667 | W27: =$F$27 -> 916.66667 | ... AA27: =$F$27 -> 916.66667
A28: =A27+1 -> 25 | B28: 44644 | C28: Gary and Laura McArdell | D28: Initiation Fees | E28: 15000 | F28: =E28/60 -> 250 | G28: 46446 | H28: =E28-SUM(I28:DP28) -> 0 | P28: =$F$28 -> 250 | Q28: =$F$28 -> 250 | R28: =$F$28 -> 250 | S28: =$F$28 -> 250 | T28: =$F$28 -> 250 | U28: =$F$28 -> 250 | V28: =$F$28 -> 250 | W28: =$F$28 -> 250 | ... BW28: =$F$28 -> 250
A29: =A28+1 -> 26 | B29: 44651 | C29: Chuck Le | D29: Initiation Fees | E29: 8755 | F29: =E29/60 -> 145.91667 | G29: 46446 | H29: =E29-SUM(I29:DP29) -> 0 | P29: =$F$29 -> 145.91667 | Q29: =$F$29 -> 145.91667 | R29: =$F$29 -> 145.91667 | S29: =$F$29 -> 145.91667 | T29: =$F$29 -> 145.91667 | U29: =$F$29 -> 145.91667 | V29: =$F$29 -> 145.91667 | W29: =$F$29 -> 145.91667 | ... BW29: =$F$29 -> 145.91667
A30: =A29+1 -> 27 | B30: 44651 | C30: Mark Jones | D30: Initiation Fees | E30: 8500 | F30: =E30/60 -> 141.66667 | G30: 46446 | H30: =E30-SUM(I30:DP30) -> 0 | P30: =$F$30 -> 141.66667 | Q30: =$F$30 -> 141.66667 | R30: =$F$30 -> 141.66667 | S30: =$F$30 -> 141.66667 | T30: =$F$30 -> 141.66667 | U30: =$F$30 -> 141.66667 | V30: =$F$30 -> 141.66667 | W30: =$F$30 -> 141.66667 | ... BW30: =$F$30 -> 141.66667
A31: =A30+1 -> 28 | B31: 44651 | C31: Audrey Few | D31: Initiation Fees | E31: 15450 | F31: =E31/60 -> 257.5 | G31: 46446 | H31: =E31-SUM(I31:DP31) -> 0 | P31: =$F$31 -> 257.5 | Q31: =$F$31 -> 257.5 | R31: =$F$31 -> 257.5 | S31: =$F$31 -> 257.5 | T31: =$F$31 -> 257.5 | U31: 14162.5
A32: =A31+1 -> 29 | B32: 44659 | C32: Piero Broccardo | D32: Initiation Fees | E32: 22500 | F32: =E32/60 -> 375 | G32: 46477 | H32: =E32-SUM(I32:DP32) -> 0 | Q32: =$F$32 -> 375 | R32: =$F$32 -> 375 | S32: =$F$32 -> 375 | T32: =$F$32 -> 375 | U32: =$F$32 -> 375 | V32: =$F$32 -> 375 | W32: =$F$32 -> 375 | X32: =$F$32 -> 375 | ... BX32: =$F$32 -> 375
A33: =A32+1 -> 30 | B33: 44689 | C33: Purvis Payne | D33: Initiation Fees | E33: 24500 | F33: =E33/60 -> 408.33333 | G33: 46507 | H33: =E33-SUM(I33:DP33) -> 0 | R33: =$F$33 -> 408.33333 | S33: =$F$33 -> 408.33333 | T33: =$F$33 -> 408.33333 | U33: =$F$33 -> 408.33333 | V33: =$F$33 -> 408.33333 | W33: =$F$33 -> 408.33333 | X33: =$F$33 -> 408.33333 | Y33: =$F$33 -> 408.33333 | ... BY33: =$F$33 -> 408.33333
A34: =A33+1 -> 31 | B34: 44772 | C34: Shawn and Julia Edwards | D34: Initiation Fees | E34: 19000 | F34: =E34/60 -> 316.66667 | G34: 46568 | H34: =E34-SUM(I34:DP34) -> 0 | T34: =$F$34 -> 316.66667 | U34: =$F$34 -> 316.66667 | V34: =$F$34 -> 316.66667 | W34: =$F$34 -> 316.66667 | X34: =$F$34 -> 316.66667 | Y34: =$F$34 -> 316.66667 | Z34: =$F$34 -> 316.66667 | AA34: =$F$34 -> 316.66667 | ... CA34: =$F$34 -> 316.66667
A35: =A34+1 -> 32 | B35: 44804 | C35: Kerry and Sirenia Sabo | D35: Initiation Fees | E35: 10500 | F35: =E35/60 -> 175 | G35: 46599 | H35: =E35-SUM(I35:DP35) -> 0 | U35: =$F$35 -> 175 | V35: =$F$35 -> 175 | W35: =$F$35 -> 175 | X35: =$F$35 -> 175 | Y35: =$F$35 -> 175 | Z35: =$F$35 -> 175 | AA35: =$F$35 -> 175 | AB35: =$F$35 -> 175 | ... CB35: =$F$35 -> 175
A36: =A35+1 -> 33 | B36: 44851 | C36: Jeremy Rhyne | D36: Initiation Fees | E36: 22500 | F36: =E36/60 -> 375 | G36: 46660 | H36: =E36-SUM(I36:DP36) -> 0 | W36: =$F$36 -> 375 | X36: =$F$36 -> 375 | Y36: =$F$36 -> 375 | Z36: =$F$36 -> 375 | AA36: =$F$36 -> 375 | AB36: =$F$36 -> 375 | AC36: =$F$36 -> 375 | AD36: =$F$36 -> 375 | ... CD36: =$F$36 -> 375
A37: =A36+1 -> 34 | B37: 44872 | C37: Jeremy Buckman and Marim Abdul | D37: Initiation Fees | E37: 21000 | F37: =E37/60 -> 350 | G37: 46691 | H37: =E37-SUM(I37:DP37) -> 0 | X37: =$F$37 -> 350 | Y37: =$F$37 -> 350 | Z37: =$F$37 -> 350 | AA37: =$F$37 -> 350 | AB37: =$F$37 -> 350 | AC37: =$F$37 -> 350 | AD37: =$F$37 -> 350 | AE37: =$F$37 -> 350 | ... CE37: =$F$37 -> 350
A38: 35 | B38: 44929 | C38: Ken Sunshine | D38: Initiation Fees | E38: 10000 | F38: =E38/60 -> 166.66667 | G38: 46722 | H38: =E38-SUM(I38:DP38) -> 0 | Z38: =$F$38 -> 166.66667 | AA38: =$F$38 -> 166.66667 | AB38: =$F$38 -> 166.66667 | AC38: =$F$38 -> 166.66667 | AD38: =$F$38 -> 166.66667 | AE38: =$F$38 -> 166.66667 | AF38: =$F$38 -> 166.66667 | AG38: =$F$38 -> 166.66667 | ... CG38: =$F$38 -> 166.66667
